Workbook

Sheet Tallerdata.com
E2: CRONOGRAMA DE ACTIVIDADES
D4: PROYECTO | E4: Sistema Web STRKE | H4: FECHA ACTUAL | I4: 46141 | M4: FECHA INICIO | P4: 46136 | U4: FECHA FIN | X4: 46218
L13: 1 | M13: =L13+1 -> 2 | N13: =M13+1 -> 3 | O13: =N13+1 -> 4 | P13: =O13+1 -> 5 | Q13: =P13+1 -> 6 | R13: =Q13+1 -> 7 | S13: =R13+1 -> 8 | T13: =S13+1 -> 9 | ... SW13: =SV13+1 -> 506
D14: CROMOGRAMA | L14: =TEXT(L16,"MMM") -> Apr | M14: =IFERROR(IF(MONTH(M16)=MONTH(L16),"",TEXT(M16,"MMM")),"") | N14: =IFERROR(IF(MONTH(N16)=MONTH(M16),"",TEXT(N16,"MMM")),"") | O14: =IFERROR(IF(MONTH(O16)=MONTH(N16),"",TEXT(O16,"MMM")),"") | P14: =IFERROR(IF(MONTH(P16)=MONTH(O16),"",TEXT(P16,"MMM")),"") | Q14: =IFERROR(IF(MONTH(Q16)=MONTH(P16),"",TEXT(Q16,"MMM")),"") | R14: =IFERROR(IF(MONTH(R16)=MONTH(Q16),"",TEXT(R16,"MMM")),"") | S14: =IFERROR(IF(MONTH(S16)=MONTH(R16),"",TEXT(S16,"MMM")),"") -> May | T14: =IFERROR(IF(MONTH(T16)=MONTH(S16),"",TEXT(T16,"MMM")),"") | ... SW14: =IFERROR(IF(MONTH(SW16)=MONTH(SV16),"",TEXT(SW16,"MMM")),"")
L15: =TEXT(L16,"ddd") -> Fri | M15: =TEXT(M16,"ddd") -> Sat | N15: =TEXT(N16,"ddd") -> Sun | O15: =TEXT(O16,"ddd") -> Mon | P15: =TEXT(P16,"ddd") -> Tue | Q15: =TEXT(Q16,"ddd") -> Wed | R15: =TEXT(R16,"ddd") -> Thu | S15: =TEXT(S16,"ddd") -> Fri | ... SW15: =TEXT(SW16,"ddd")
D16: ACTIVIDADES | E16: RESPONSABLE | F16: FECHA INI | G16: Nº DÍAS | H16: FECHA FIN | I16: AVANCE | J16: ESTADO | L16: =VLOOKUP(L13,Fechas!$N$4:$O$509,2,0) -> 46136 | M16: =VLOOKUP(M13,Fechas!$N$4:$O$509,2,0) -> 46137 | N16: =VLOOKUP(N13,Fechas!$N$4:$O$509,2,0) -> 46138 | O16: =VLOOKUP(O13,Fechas!$N$4:$O$509,2,0) -> 46139 | P16: =VLOOKUP(P13,Fechas!$N$4:$O$509,2,0) -> 46140 | Q16: =VLOOKUP(Q13,Fechas!$N$4:$O$509,2,0) -> 46141 | R16: =VLOOKUP(R13,Fechas!$N$4:$O$509,2,0) -> 46142 | S16: =VLOOKUP(S13,Fechas!$N$4:$O$509,2,0) -> 46143 | ... SW16: =VLOOKUP(SW13,Fechas!$N$4:$O$509,2,0)
D18: FASE 1
D19: Proyecto Spring boot base | E19: Yimy Flores | F19: 46136 | G19: 1 | H19: =(F19+G19)-1 -> 46136 | I19: 1 | J19: Completado | L19: =IF($I19>0%,IF(AND(L$16>=$F19,L$16<$F19+($G19*$I19)),"➤",""),"") -> ➤ | M19: =IF($I19>0%,IF(AND(M$16>=$F19,M$16<$F19+($G19*$I19)),"➤",""),"") | N19: =IF($I19>0%,IF(AND(N$16>=$F19,N$16<$F19+($G19*$I19)),"➤",""),"") | O19: =IF($I19>0%,IF(AND(O$16>=$F19,O$16<$F19+($G19*$I19)),"➤",""),"") | P19: =IF($I19>0%,IF(AND(P$16>=$F19,P$16<$F19+($G19*$I19)),"➤",""),"") | Q19: =IF($I19>0%,IF(AND(Q$16>=$F19,Q$16<$F19+($G19*$I19)),"➤",""),"") | R19: =IF($I19>0%,IF(AND(R$16>=$F19,R$16<$F19+($G19*$I19)),"➤",""),"") | S19: =IF($I19>0%,IF(AND(S$16>=$F19,S$16<$F19+($G19*$I19)),"➤",""),"") | ... SW19: =IF($I19>0%,IF(AND(SW$16>=$F19,SW$16<$F19+($G19*$I19)),"➤",""),"")
D20: Repositorio y su estructura | E20: Yimy Flores | F20: 46136 | G20: 1 | H20: =(F20+G20)-1 -> 46136 | I20: 1 | J20: Completado | L20: =IF($I20>0%,IF(AND(L$16>=$F20,L$16<$F20+($G20*$I20)),"➤",""),"") -> ➤ | M20: =IF($I20>0%,IF(AND(M$16>=$F20,M$16<$F20+($G20*$I20)),"➤",""),"") | N20: =IF($I20>0%,IF(AND(N$16>=$F20,N$16<$F20+($G20*$I20)),"➤",""),"") | O20: =IF($I20>0%,IF(AND(O$16>=$F20,O$16<$F20+($G20*$I20)),"➤",""),"") | P20: =IF($I20>0%,IF(AND(P$16>=$F20,P$16<$F20+($G20*$I20)),"➤",""),"") | Q20: =IF($I20>0%,IF(AND(Q$16>=$F20,Q$16<$F20+($G20*$I20)),"➤",""),"") | R20: =IF($I20>0%,IF(AND(R$16>=$F20,R$16<$F20+($G20*$I20)),"➤",""),"") | S20: =IF($I20>0%,IF(AND(S$16>=$F20,S$16<$F20+($G20*$I20)),"➤",""),"") | ... SW20: =IF($I20>0%,IF(AND(SW$16>=$F20,SW$16<$F20+($G20*$I20)),"➤",""),"")
D21: Docs Justifcación | E21: Edson Alabrin | F21: 46137 | G21: 2 | H21: =(F21+G21)-1 -> 46138 | I21: 1 | J21: Completado | L21: =IF($I21>0%,IF(AND(L$16>=$F21,L$16<$F21+($G21*$I21)),"➤",""),"") | M21: =IF($I21>0%,IF(AND(M$16>=$F21,M$16<$F21+($G21*$I21)),"➤",""),"") -> ➤ | N21: =IF($I21>0%,IF(AND(N$16>=$F21,N$16<$F21+($G21*$I21)),"➤",""),"") -> ➤ | O21: =IF($I21>0%,IF(AND(O$16>=$F21,O$16<$F21+($G21*$I21)),"➤",""),"") | P21: =IF($I21>0%,IF(AND(P$16>=$F21,P$16<$F21+($G21*$I21)),"➤",""),"") | Q21: =IF($I21>0%,IF(AND(Q$16>=$F21,Q$16<$F21+($G21*$I21)),"➤",""),"") | R21: =IF($I21>0%,IF(AND(R$16>=$F21,R$16<$F21+($G21*$I21)),"➤",""),"") | S21: =IF($I21>0%,IF(AND(S$16>=$F21,S$16<$F21+($G21*$I21)),"➤",""),"") | ... SW21: =IF($I21>0%,IF(AND(SW$16>=$F21,SW$16<$F21+($G21*$I21)),"➤",""),"")
D22: Docs Objetivos | E22: Hector Montes | F22: 46137 | G22: 2 | H22: =(F22+G22)-1 -> 46138 | I22: 1 | J22: Completado | L22: =IF($I22>0%,IF(AND(L$16>=$F22,L$16<$F22+($G22*$I22)),"➤",""),"") | M22: =IF($I22>0%,IF(AND(M$16>=$F22,M$16<$F22+($G22*$I22)),"➤",""),"") -> ➤ | N22: =IF($I22>0%,IF(AND(N$16>=$F22,N$16<$F22+($G22*$I22)),"➤",""),"") -> ➤ | O22: =IF($I22>0%,IF(AND(O$16>=$F22,O$16<$F22+($G22*$I22)),"➤",""),"") | P22: =IF($I22>0%,IF(AND(P$16>=$F22,P$16<$F22+($G22*$I22)),"➤",""),"") | Q22: =IF($I22>0%,IF(AND(Q$16>=$F22,Q$16<$F22+($G22*$I22)),"➤",""),"") | R22: =IF($I22>0%,IF(AND(R$16>=$F22,R$16<$F22+($G22*$I22)),"➤",""),"") | S22: =IF($I22>0%,IF(AND(S$16>=$F22,S$16<$F22+($G22*$I22)),"➤",""),"") | ... SW22: =IF($I22>0%,IF(AND(SW$16>=$F22,SW$16<$F22+($G22*$I22)),"➤",""),"")
D23: Docs Marco teórico | E23: Yadhira Saavedra | F23: 46137 | G23: 2 | H23: =(F23+G23)-1 -> 46138 | I23: 1 | J23: Completado | L23: =IF($I23>0%,IF(AND(L$16>=$F23,L$16<$F23+($G23*$I23)),"➤",""),"") | M23: =IF($I23>0%,IF(AND(M$16>=$F23,M$16<$F23+($G23*$I23)),"➤",""),"") -> ➤ | N23: =IF($I23>0%,IF(AND(N$16>=$F23,N$16<$F23+($G23*$I23)),"➤",""),"") -> ➤ | O23: =IF($I23>0%,IF(AND(O$16>=$F23,O$16<$F23+($G23*$I23)),"➤",""),"") | P23: =IF($I23>0%,IF(AND(P$16>=$F23,P$16<$F23+($G23*$I23)),"➤",""),"") | Q23: =IF($I23>0%,IF(AND(Q$16>=$F23,Q$16<$F23+($G23*$I23)),"➤",""),"") | R23: =IF($I23>0%,IF(AND(R$16>=$F23,R$16<$F23+($G23*$I23)),"➤",""),"") | S23: =IF($I23>0%,IF(AND(S$16>=$F23,S$16<$F23+($G23*$I23)),"➤",""),"") | ... SW23: =IF($I23>0%,IF(AND(SW$16>=$F23,SW$16<$F23+($G23*$I23)),"➤",""),"")
D24: Readme: Informe general | E24: Yadhira Saavedra | F24: 46139 | G24: 1 | H24: =(F24+G24)-1 -> 46139 | I24: 1 | J24: Completado | L24: =IF($I24>0%,IF(AND(L$16>=$F24,L$16<$F24+($G24*$I24)),"➤",""),"") | M24: =IF($I24>0%,IF(AND(M$16>=$F24,M$16<$F24+($G24*$I24)),"➤",""),"") | N24: =IF($I24>0%,IF(AND(N$16>=$F24,N$16<$F24+($G24*$I24)),"➤",""),"") | O24: =IF($I24>0%,IF(AND(O$16>=$F24,O$16<$F24+($G24*$I24)),"➤",""),"") -> ➤ | P24: =IF($I24>0%,IF(AND(P$16>=$F24,P$16<$F24+($G24*$I24)),"➤",""),"") | Q24: =IF($I24>0%,IF(AND(Q$16>=$F24,Q$16<$F24+($G24*$I24)),"➤",""),"") | R24: =IF($I24>0%,IF(AND(R$16>=$F24,R$16<$F24+($G24*$I24)),"➤",""),"") | S24: =IF($I24>0%,IF(AND(S$16>=$F24,S$16<$F24+($G24*$I24)),"➤",""),"") | ... SW24: =IF($I24>0%,IF(AND(SW$16>=$F24,SW$16<$F24+($G24*$I24)),"➤",""),"")
D25: Readme: agredicimientos | E25: Yadhira Saavedra | F25: 46140 | G25: 1 | H25: =(F25+G25)-1 -> 46140 | I25: 1 | J25: Completado | L25: =IF($I25>0%,IF(AND(L$16>=$F25,L$16<$F25+($G25*$I25)),"➤",""),"") | M25: =IF($I25>0%,IF(AND(M$16>=$F25,M$16<$F25+($G25*$I25)),"➤",""),"") | N25: =IF($I25>0%,IF(AND(N$16>=$F25,N$16<$F25+($G25*$I25)),"➤",""),"") | O25: =IF($I25>0%,IF(AND(O$16>=$F25,O$16<$F25+($G25*$I25)),"➤",""),"") | P25: =IF($I25>0%,IF(AND(P$16>=$F25,P$16<$F25+($G25*$I25)),"➤",""),"") -> ➤ | Q25: =IF($I25>0%,IF(AND(Q$16>=$F25,Q$16<$F25+($G25*$I25)),"➤",""),"") | R25: =IF($I25>0%,IF(AND(R$16>=$F25,R$16<$F25+($G25*$I25)),"➤",""),"") | S25: =IF($I25>0%,IF(AND(S$16>=$F25,S$16<$F25+($G25*$I25)),"➤",""),"") | ... SW25: =IF($I25>0%,IF(AND(SW$16>=$F25,SW$16<$F25+($G25*$I25)),"➤",""),"")
D26: Readme: Resumen y Abstract | E26: Hector Montes | F26: 46140 | G26: 1 | H26: =(F26+G26)-1 -> 46140 | I26: 1 | J26: Completado | L26: =IF($I26>0%,IF(AND(L$16>=$F26,L$16<$F26+($G26*$I26)),"➤",""),"") | M26: =IF($I26>0%,IF(AND(M$16>=$F26,M$16<$F26+($G26*$I26)),"➤",""),"") | N26: =IF($I26>0%,IF(AND(N$16>=$F26,N$16<$F26+($G26*$I26)),"➤",""),"") | O26: =IF($I26>0%,IF(AND(O$16>=$F26,O$16<$F26+($G26*$I26)),"➤",""),"") | P26: =IF($I26>0%,IF(AND(P$16>=$F26,P$16<$F26+($G26*$I26)),"➤",""),"") -> ➤ | Q26: =IF($I26>0%,IF(AND(Q$16>=$F26,Q$16<$F26+($G26*$I26)),"➤",""),"") | R26: =IF($I26>0%,IF(AND(R$16>=$F26,R$16<$F26+($G26*$I26)),"➤",""),"") | S26: =IF($I26>0%,IF(AND(S$16>=$F26,S$16<$F26+($G26*$I26)),"➤",""),"") | ... SW26: =IF($I26>0%,IF(AND(SW$16>=$F26,SW$16<$F26+($G26*$I26)),"➤",""),"")
D27: Readme: Realidad problemática | E27: Edson Alabrin | F27: 46140 | G27: 1 | H27: =(F27+G27)-1 -> 46140 | I27: 1 | J27: Completado | P27: =IF($I27>0%,IF(AND(P$16>=$F27,P$16<$F27+($G27*$I27)),"➤",""),"") -> ➤
D28: Readme: Justificación | E28: Edson Alabrin | F28: 46140 | G28: 1 | H28: =(F28+G28)-1 -> 46140 | I28: 1 | J28: Completado | P28: =IF($I28>0%,IF(AND(P$16>=$F28,P$16<$F28+($G28*$I28)),"➤",""),"") -> ➤
D29: Readme: Objetivos | E29: Hector Montes | F29: 46140 | G29: 1 | H29: 46140 | I29: 1 | J29: Completado | P29: =IF($I29>0%,IF(AND(P$16>=$F29,P$16<$F29+($G29*$I29)),"➤",""),"") -> ➤
D30: Readme: Marco teorico y metodología | E30: Yadhira Saavedra | F30: 46140 | G30: 1 | H30: 46140 | I30: 1 | J30: Completado | L30: =IF($I30>0%,IF(AND(L$16>=$F30,L$16<$F30+($G30*$I30)),"➤",""),"") | M30: =IF($I30>0%,IF(AND(M$16>=$F30,M$16<$F30+($G30*$I30)),"➤",""),"") | N30: =IF($I30>0%,IF(AND(N$16>=$F30,N$16<$F30+($G30*$I30)),"➤",""),"") | O30: =IF($I30>0%,IF(AND(O$16>=$F30,O$16<$F30+($G30*$I30)),"➤",""),"") | P30: =IF($I30>0%,IF(AND(P$16>=$F30,P$16<$F30+($G30*$I30)),"➤",""),"") -> ➤ | Q30: =IF($I30>0%,IF(AND(Q$16>=$F30,Q$16<$F30+($G30*$I30)),"➤",""),"") | R30: =IF($I30>0%,IF(AND(R$16>=$F30,R$16<$F30+($G30*$I30)),"➤",""),"") | S30: =IF($I30>0%,IF(AND(S$16>=$F30,S$16<$F30+($G30*$I30)),"➤",""),"") | ... SW30: =IF($I30>0%,IF(AND(SW$16>=$F30,SW$16<$F30+($G30*$I30)),"➤",""),"")
D31: FASE 2
F32: 44155 | G32: 3 | H32: =(F32+G32)-1 -> 44157 | I32: 0.9 | L32: =IF($I32>0%,IF(AND(L$16>=$F32,L$16<$F32+($G32*$I32)),"➤",""),"") | M32: =IF($I32>0%,IF(AND(M$16>=$F32,M$16<$F32+($G32*$I32)),"➤",""),"") | N32: =IF($I32>0%,IF(AND(N$16>=$F32,N$16<$F32+($G32*$I32)),"➤",""),"") | O32: =IF($I32>0%,IF(AND(O$16>=$F32,O$16<$F32+($G32*$I32)),"➤",""),"") | P32: =IF($I32>0%,IF(AND(P$16>=$F32,P$16<$F32+($G32*$I32)),"➤",""),"") | Q32: =IF($I32>0%,IF(AND(Q$16>=$F32,Q$16<$F32+($G32*$I32)),"➤",""),"") | R32: =IF($I32>0%,IF(AND(R$16>=$F32,R$16<$F32+($G32*$I32)),"➤",""),"") | S32: =IF($I32>0%,IF(AND(S$16>=$F32,S$16<$F32+($G32*$I32)),"➤",""),"") | ... SW32: =IF($I32>0%,IF(AND(SW$16>=$F32,SW$16<$F32+($G32*$I32)),"➤",""),"")
F33: 44155 | G33: 4 | H33: =(F33+G33)-1 -> 44158 | I33: 0.95 | L33: =IF($I33>0%,IF(AND(L$16>=$F33,L$16<$F33+($G33*$I33)),"➤",""),"") | M33: =IF($I33>0%,IF(AND(M$16>=$F33,M$16<$F33+($G33*$I33)),"➤",""),"") | N33: =IF($I33>0%,IF(AND(N$16>=$F33,N$16<$F33+($G33*$I33)),"➤",""),"") | O33: =IF($I33>0%,IF(AND(O$16>=$F33,O$16<$F33+($G33*$I33)),"➤",""),"") | P33: =IF($I33>0%,IF(AND(P$16>=$F33,P$16<$F33+($G33*$I33)),"➤",""),"") | Q33: =IF($I33>0%,IF(AND(Q$16>=$F33,Q$16<$F33+($G33*$I33)),"➤",""),"") | R33: =IF($I33>0%,IF(AND(R$16>=$F33,R$16<$F33+($G33*$I33)),"➤",""),"") | S33: =IF($I33>0%,IF(AND(S$16>=$F33,S$16<$F33+($G33*$I33)),"➤",""),"") | ... SW33: =IF($I33>0%,IF(AND(SW$16>=$F33,SW$16<$F33+($G33*$I33)),"➤",""),"")
F34: 44147 | G34: 5 | H34: =(F34+G34)-1 -> 44151 | I34: 1 | L34: =IF($I34>0%,IF(AND(L$16>=$F34,L$16<$F34+($G34*$I34)),"➤",""),"") | M34: =IF($I34>0%,IF(AND(M$16>=$F34,M$16<$F34+($G34*$I34)),"➤",""),"") | N34: =IF($I34>0%,IF(AND(N$16>=$F34,N$16<$F34+($G34*$I34)),"➤",""),"") | O34: =IF($I34>0%,IF(AND(O$16>=$F34,O$16<$F34+($G34*$I34)),"➤",""),"") | P34: =IF($I34>0%,IF(AND(P$16>=$F34,P$16<$F34+($G34*$I34)),"➤",""),"") | Q34: =IF($I34>0%,IF(AND(Q$16>=$F34,Q$16<$F34+($G34*$I34)),"➤",""),"") | R34: =IF($I34>0%,IF(AND(R$16>=$F34,R$16<$F34+($G34*$I34)),"➤",""),"") | S34: =IF($I34>0%,IF(AND(S$16>=$F34,S$16<$F34+($G34*$I34)),"➤",""),"") | ... SW34: =IF($I34>0%,IF(AND(SW$16>=$F34,SW$16<$F34+($G34*$I34)),"➤",""),"")
F35: 44148 | G35: 3 | H35: =(F35+G35)-1 -> 44150 | I35: 1 | L35: =IF($I35>0%,IF(AND(L$16>=$F35,L$16<$F35+($G35*$I35)),"➤",""),"") | M35: =IF($I35>0%,IF(AND(M$16>=$F35,M$16<$F35+($G35*$I35)),"➤",""),"") | N35: =IF($I35>0%,IF(AND(N$16>=$F35,N$16<$F35+($G35*$I35)),"➤",""),"") | O35: =IF($I35>0%,IF(AND(O$16>=$F35,O$16<$F35+($G35*$I35)),"➤",""),"") | P35: =IF($I35>0%,IF(AND(P$16>=$F35,P$16<$F35+($G35*$I35)),"➤",""),"") | Q35: =IF($I35>0%,IF(AND(Q$16>=$F35,Q$16<$F35+($G35*$I35)),"➤",""),"") | R35: =IF($I35>0%,IF(AND(R$16>=$F35,R$16<$F35+($G35*$I35)),"➤",""),"") | S35: =IF($I35>0%,IF(AND(S$16>=$F35,S$16<$F35+($G35*$I35)),"➤",""),"") | ... SW35: =IF($I35>0%,IF(AND(SW$16>=$F35,SW$16<$F35+($G35*$I35)),"➤",""),"")
F36: 44150 | G36: 3 | H36: =(F36+G36)-1 -> 44152 | I36: 1 | L36: =IF($I36>0%,IF(AND(L$16>=$F36,L$16<$F36+($G36*$I36)),"➤",""),"") | M36: =IF($I36>0%,IF(AND(M$16>=$F36,M$16<$F36+($G36*$I36)),"➤",""),"") | N36: =IF($I36>0%,IF(AND(N$16>=$F36,N$16<$F36+($G36*$I36)),"➤",""),"") | O36: =IF($I36>0%,IF(AND(O$16>=$F36,O$16<$F36+($G36*$I36)),"➤",""),"") | P36: =IF($I36>0%,IF(AND(P$16>=$F36,P$16<$F36+($G36*$I36)),"➤",""),"") | Q36: =IF($I36>0%,IF(AND(Q$16>=$F36,Q$16<$F36+($G36*$I36)),"➤",""),"") | R36: =IF($I36>0%,IF(AND(R$16>=$F36,R$16<$F36+($G36*$I36)),"➤",""),"") | S36: =IF($I36>0%,IF(AND(S$16>=$F36,S$16<$F36+($G36*$I36)),"➤",""),"") | ... SW36: =IF($I36>0%,IF(AND(SW$16>=$F36,SW$16<$F36+($G36*$I36)),"➤",""),"")
F37: 44151 | G37: 2 | H37: =(F37+G37)-1 -> 44152 | I37: 1 | L37: =IF($I37>0%,IF(AND(L$16>=$F37,L$16<$F37+($G37*$I37)),"➤",""),"") | M37: =IF($I37>0%,IF(AND(M$16>=$F37,M$16<$F37+($G37*$I37)),"➤",""),"") | N37: =IF($I37>0%,IF(AND(N$16>=$F37,N$16<$F37+($G37*$I37)),"➤",""),"") | O37: =IF($I37>0%,IF(AND(O$16>=$F37,O$16<$F37+($G37*$I37)),"➤",""),"") | P37: =IF($I37>0%,IF(AND(P$16>=$F37,P$16<$F37+($G37*$I37)),"➤",""),"") | Q37: =IF($I37>0%,IF(AND(Q$16>=$F37,Q$16<$F37+($G37*$I37)),"➤",""),"") | R37: =IF($I37>0%,IF(AND(R$16>=$F37,R$16<$F37+($G37*$I37)),"➤",""),"") | S37: =IF($I37>0%,IF(AND(S$16>=$F37,S$16<$F37+($G37*$I37)),"➤",""),"") | ... SW37: =IF($I37>0%,IF(AND(SW$16>=$F37,SW$16<$F37+($G37*$I37)),"➤",""),"")
F38: 44153 | G38: 2 | H38: =(F38+G38)-1 -> 44154 | I38: 0.8 | L38: =IF($I38>0%,IF(AND(L$16>=$F38,L$16<$F38+($G38*$I38)),"➤",""),"") | M38: =IF($I38>0%,IF(AND(M$16>=$F38,M$16<$F38+($G38*$I38)),"➤",""),"") | N38: =IF($I38>0%,IF(AND(N$16>=$F38,N$16<$F38+($G38*$I38)),"➤",""),"") | O38: =IF($I38>0%,IF(AND(O$16>=$F38,O$16<$F38+($G38*$I38)),"➤",""),"") | P38: =IF($I38>0%,IF(AND(P$16>=$F38,P$16<$F38+($G38*$I38)),"➤",""),"") | Q38: =IF($I38>0%,IF(AND(Q$16>=$F38,Q$16<$F38+($G38*$I38)),"➤",""),"") | R38: =IF($I38>0%,IF(AND(R$16>=$F38,R$16<$F38+($G38*$I38)),"➤",""),"") | S38: =IF($I38>0%,IF(AND(S$16>=$F38,S$16<$F38+($G38*$I38)),"➤",""),"") | ... SW38: =IF($I38>0%,IF(AND(SW$16>=$F38,SW$16<$F38+($G38*$I38)),"➤",""),"")
F39: 44155 | G39: 4 | H39: =(F39+G39)-1 -> 44158 | I39: 0.9 | L39: =IF($I39>0%,IF(AND(L$16>=$F39,L$16<$F39+($G39*$I39)),"➤",""),"") | M39: =IF($I39>0%,IF(AND(M$16>=$F39,M$16<$F39+($G39*$I39)),"➤",""),"") | N39: =IF($I39>0%,IF(AND(N$16>=$F39,N$16<$F39+($G39*$I39)),"➤",""),"") | O39: =IF($I39>0%,IF(AND(O$16>=$F39,O$16<$F39+($G39*$I39)),"➤",""),"") | P39: =IF($I39>0%,IF(AND(P$16>=$F39,P$16<$F39+($G39*$I39)),"➤",""),"") | Q39: =IF($I39>0%,IF(AND(Q$16>=$F39,Q$16<$F39+($G39*$I39)),"➤",""),"") | R39: =IF($I39>0%,IF(AND(R$16>=$F39,R$16<$F39+($G39*$I39)),"➤",""),"") | S39: =IF($I39>0%,IF(AND(S$16>=$F39,S$16<$F39+($G39*$I39)),"➤",""),"") | ... SW39: =IF($I39>0%,IF(AND(SW$16>=$F39,SW$16<$F39+($G39*$I39)),"➤",""),"")
F40: 44157 | G40: 4 | H40: =(F40+G40)-1 -> 44160 | I40: 0.5 | L40: =IF($I40>0%,IF(AND(L$16>=$F40,L$16<$F40+($G40*$I40)),"➤",""),"") | M40: =IF($I40>0%,IF(AND(M$16>=$F40,M$16<$F40+($G40*$I40)),"➤",""),"") | N40: =IF($I40>0%,IF(AND(N$16>=$F40,N$16<$F40+($G40*$I40)),"➤",""),"") | O40: =IF($I40>0%,IF(AND(O$16>=$F40,O$16<$F40+($G40*$I40)),"➤",""),"") | P40: =IF($I40>0%,IF(AND(P$16>=$F40,P$16<$F40+($G40*$I40)),"➤",""),"") | Q40: =IF($I40>0%,IF(AND(Q$16>=$F40,Q$16<$F40+($G40*$I40)),"➤",""),"") | R40: =IF($I40>0%,IF(AND(R$16>=$F40,R$16<$F40+($G40*$I40)),"➤",""),"") | S40: =IF($I40>0%,IF(AND(S$16>=$F40,S$16<$F40+($G40*$I40)),"➤",""),"") | ... SW40: =IF($I40>0%,IF(AND(SW$16>=$F40,SW$16<$F40+($G40*$I40)),"➤",""),"")
F41: 44161 | G41: 6 | H41: =(F41+G41)-1 -> 44166 | I41: 0 | L41: =IF($I41>0%,IF(AND(L$16>=$F41,L$16<$F41+($G41*$I41)),"➤",""),"") | M41: =IF($I41>0%,IF(AND(M$16>=$F41,M$16<$F41+($G41*$I41)),"➤",""),"") | N41: =IF($I41>0%,IF(AND(N$16>=$F41,N$16<$F41+($G41*$I41)),"➤",""),"") | O41: =IF($I41>0%,IF(AND(O$16>=$F41,O$16<$F41+($G41*$I41)),"➤",""),"") | P41: =IF($I41>0%,IF(AND(P$16>=$F41,P$16<$F41+($G41*$I41)),"➤",""),"") | Q41: =IF($I41>0%,IF(AND(Q$16>=$F41,Q$16<$F41+($G41*$I41)),"➤",""),"") | R41: =IF($I41>0%,IF(AND(R$16>=$F41,R$16<$F41+($G41*$I41)),"➤",""),"") | S41: =IF($I41>0%,IF(AND(S$16>=$F41,S$16<$F41+($G41*$I41)),"➤",""),"") | ... SW41: =IF($I41>0%,IF(AND(SW$16>=$F41,SW$16<$F41+($G41*$I41)),"➤",""),"")
D42: FASE 3
F43: 44162 | G43: 6 | H43: =(F43+G43)-1 -> 44167 | I43: 0 | L43: =IF($I43>0%,IF(AND(L$16>=$F43,L$16<$F43+($G43*$I43)),"➤",""),"") | M43: =IF($I43>0%,IF(AND(M$16>=$F43,M$16<$F43+($G43*$I43)),"➤",""),"") | N43: =IF($I43>0%,IF(AND(N$16>=$F43,N$16<$F43+($G43*$I43)),"➤",""),"") | O43: =IF($I43>0%,IF(AND(O$16>=$F43,O$16<$F43+($G43*$I43)),"➤",""),"") | P43: =IF($I43>0%,IF(AND(P$16>=$F43,P$16<$F43+($G43*$I43)),"➤",""),"") | Q43: =IF($I43>0%,IF(AND(Q$16>=$F43,Q$16<$F43+($G43*$I43)),"➤",""),"") | R43: =IF($I43>0%,IF(AND(R$16>=$F43,R$16<$F43+($G43*$I43)),"➤",""),"") | S43: =IF($I43>0%,IF(AND(S$16>=$F43,S$16<$F43+($G43*$I43)),"➤",""),"") | ... SW43: =IF($I43>0%,IF(AND(SW$16>=$F43,SW$16<$F43+($G43*$I43)),"➤",""),"")
F44: 44163 | G44: 2 | H44: =(F44+G44)-1 -> 44164 | I44: 0 | L44: =IF($I44>0%,IF(AND(L$16>=$F44,L$16<$F44+($G44*$I44)),"➤",""),"") | M44: =IF($I44>0%,IF(AND(M$16>=$F44,M$16<$F44+($G44*$I44)),"➤",""),"") | N44: =IF($I44>0%,IF(AND(N$16>=$F44,N$16<$F44+($G44*$I44)),"➤",""),"") | O44: =IF($I44>0%,IF(AND(O$16>=$F44,O$16<$F44+($G44*$I44)),"➤",""),"") | P44: =IF($I44>0%,IF(AND(P$16>=$F44,P$16<$F44+($G44*$I44)),"➤",""),"") | Q44: =IF($I44>0%,IF(AND(Q$16>=$F44,Q$16<$F44+($G44*$I44)),"➤",""),"") | R44: =IF($I44>0%,IF(AND(R$16>=$F44,R$16<$F44+($G44*$I44)),"➤",""),"") | S44: =IF($I44>0%,IF(AND(S$16>=$F44,S$16<$F44+($G44*$I44)),"➤",""),"") | ... SW44: =IF($I44>0%,IF(AND(SW$16>=$F44,SW$16<$F44+($G44*$I44)),"➤",""),"")
F45: 44165 | G45: 8 | H45: =(F45+G45)-1 -> 44172 | I45: 0 | L45: =IF($I45>0%,IF(AND(L$16>=$F45,L$16<$F45+($G45*$I45)),"➤",""),"") | M45: =IF($I45>0%,IF(AND(M$16>=$F45,M$16<$F45+($G45*$I45)),"➤",""),"") | N45: =IF($I45>0%,IF(AND(N$16>=$F45,N$16<$F45+($G45*$I45)),"➤",""),"") | O45: =IF($I45>0%,IF(AND(O$16>=$F45,O$16<$F45+($G45*$I45)),"➤",""),"") | P45: =IF($I45>0%,IF(AND(P$16>=$F45,P$16<$F45+($G45*$I45)),"➤",""),"") | Q45: =IF($I45>0%,IF(AND(Q$16>=$F45,Q$16<$F45+($G45*$I45)),"➤",""),"") | R45: =IF($I45>0%,IF(AND(R$16>=$F45,R$16<$F45+($G45*$I45)),"➤",""),"") | S45: =IF($I45>0%,IF(AND(S$16>=$F45,S$16<$F45+($G45*$I45)),"➤",""),"") | ... SW45: =IF($I45>0%,IF(AND(SW$16>=$F45,SW$16<$F45+($G45*$I45)),"➤",""),"")
F46: 44166 | G46: 10 | H46: =(F46+G46)-1 -> 44175 | I46: 0 | L46: =IF($I46>0%,IF(AND(L$16>=$F46,L$16<$F46+($G46*$I46)),"➤",""),"") | M46: =IF($I46>0%,IF(AND(M$16>=$F46,M$16<$F46+($G46*$I46)),"➤",""),"") | N46: =IF($I46>0%,IF(AND(N$16>=$F46,N$16<$F46+($G46*$I46)),"➤",""),"") | O46: =IF($I46>0%,IF(AND(O$16>=$F46,O$16<$F46+($G46*$I46)),"➤",""),"") | P46: =IF($I46>0%,IF(AND(P$16>=$F46,P$16<$F46+($G46*$I46)),"➤",""),"") | Q46: =IF($I46>0%,IF(AND(Q$16>=$F46,Q$16<$F46+($G46*$I46)),"➤",""),"") | R46: =IF($I46>0%,IF(AND(R$16>=$F46,R$16<$F46+($G46*$I46)),"➤",""),"") | S46: =IF($I46>0%,IF(AND(S$16>=$F46,S$16<$F46+($G46*$I46)),"➤",""),"") | ... SW46: =IF($I46>0%,IF(AND(SW$16>=$F46,SW$16<$F46+($G46*$I46)),"➤",""),"")
F47: 44169 | G47: 5 | H47: =(F47+G47)-1 -> 44173 | I47: 0 | L47: =IF($I47>0%,IF(AND(L$16>=$F47,L$16<$F47+($G47*$I47)),"➤",""),"") | M47: =IF($I47>0%,IF(AND(M$16>=$F47,M$16<$F47+($G47*$I47)),"➤",""),"") | N47: =IF($I47>0%,IF(AND(N$16>=$F47,N$16<$F47+($G47*$I47)),"➤",""),"") | O47: =IF($I47>0%,IF(AND(O$16>=$F47,O$16<$F47+($G47*$I47)),"➤",""),"") | P47: =IF($I47>0%,IF(AND(P$16>=$F47,P$16<$F47+($G47*$I47)),"➤",""),"") | Q47: =IF($I47>0%,IF(AND(Q$16>=$F47,Q$16<$F47+($G47*$I47)),"➤",""),"") | R47: =IF($I47>0%,IF(AND(R$16>=$F47,R$16<$F47+($G47*$I47)),"➤",""),"") | S47: =IF($I47>0%,IF(AND(S$16>=$F47,S$16<$F47+($G47*$I47)),"➤",""),"") | ... SW47: =IF($I47>0%,IF(AND(SW$16>=$F47,SW$16<$F47+($G47*$I47)),"➤",""),"")
F48: 44175 | G48: 5 | H48: =(F48+G48)-1 -> 44179 | I48: 0 | L48: =IF($I48>0%,IF(AND(L$16>=$F48,L$16<$F48+($G48*$I48)),"➤",""),"") | M48: =IF($I48>0%,IF(AND(M$16>=$F48,M$16<$F48+($G48*$I48)),"➤",""),"") | N48: =IF($I48>0%,IF(AND(N$16>=$F48,N$16<$F48+($G48*$I48)),"➤",""),"") | O48: =IF($I48>0%,IF(AND(O$16>=$F48,O$16<$F48+($G48*$I48)),"➤",""),"") | P48: =IF($I48>0%,IF(AND(P$16>=$F48,P$16<$F48+($G48*$I48)),"➤",""),"") | Q48: =IF($I48>0%,IF(AND(Q$16>=$F48,Q$16<$F48+($G48*$I48)),"➤",""),"") | R48: =IF($I48>0%,IF(AND(R$16>=$F48,R$16<$F48+($G48*$I48)),"➤",""),"") | S48: =IF($I48>0%,IF(AND(S$16>=$F48,S$16<$F48+($G48*$I48)),"➤",""),"") | ... SW48: =IF($I48>0%,IF(AND(SW$16>=$F48,SW$16<$F48+($G48*$I48)),"➤",""),"")
F49: 44178 | G49: 5 | H49: =(F49+G49)-1 -> 44182 | I49: 0 | L49: =IF($I49>0%,IF(AND(L$16>=$F49,L$16<$F49+($G49*$I49)),"➤",""),"") | M49: =IF($I49>0%,IF(AND(M$16>=$F49,M$16<$F49+($G49*$I49)),"➤",""),"") | N49: =IF($I49>0%,IF(AND(N$16>=$F49,N$16<$F49+($G49*$I49)),"➤",""),"") | O49: =IF($I49>0%,IF(AND(O$16>=$F49,O$16<$F49+($G49*$I49)),"➤",""),"") | P49: =IF($I49>0%,IF(AND(P$16>=$F49,P$16<$F49+($G49*$I49)),"➤",""),"") | Q49: =IF($I49>0%,IF(AND(Q$16>=$F49,Q$16<$F49+($G49*$I49)),"➤",""),"") | R49: =IF($I49>0%,IF(AND(R$16>=$F49,R$16<$F49+($G49*$I49)),"➤",""),"") | S49: =IF($I49>0%,IF(AND(S$16>=$F49,S$16<$F49+($G49*$I49)),"➤",""),"") | ... SW49: =IF($I49>0%,IF(AND(SW$16>=$F49,SW$16<$F49+($G49*$I49)),"➤",""),"")
F50: 44180 | G50: 4 | H50: =(F50+G50)-1 -> 44183 | I50: 0 | L50: =IF($I50>0%,IF(AND(L$16>=$F50,L$16<$F50+($G50*$I50)),"➤",""),"") | M50: =IF($I50>0%,IF(AND(M$16>=$F50,M$16<$F50+($G50*$I50)),"➤",""),"") | N50: =IF($I50>0%,IF(AND(N$16>=$F50,N$16<$F50+($G50*$I50)),"➤",""),"") | O50: =IF($I50>0%,IF(AND(O$16>=$F50,O$16<$F50+($G50*$I50)),"➤",""),"") | P50: =IF($I50>0%,IF(AND(P$16>=$F50,P$16<$F50+($G50*$I50)),"➤",""),"") | Q50: =IF($I50>0%,IF(AND(Q$16>=$F50,Q$16<$F50+($G50*$I50)),"➤",""),"") | R50: =IF($I50>0%,IF(AND(R$16>=$F50,R$16<$F50+($G50*$I50)),"➤",""),"") | S50: =IF($I50>0%,IF(AND(S$16>=$F50,S$16<$F50+($G50*$I50)),"➤",""),"") | ... SW50: =IF($I50>0%,IF(AND(SW$16>=$F50,SW$16<$F50+($G50*$I50)),"➤",""),"")
F51: 44181 | G51: 3 | H51: =(F51+G51)-1 -> 44183 | I51: 0 | L51: =IF($I51>0%,IF(AND(L$16>=$F51,L$16<$F51+($G51*$I51)),"➤",""),"") | M51: =IF($I51>0%,IF(AND(M$16>=$F51,M$16<$F51+($G51*$I51)),"➤",""),"") | N51: =IF($I51>0%,IF(AND(N$16>=$F51,N$16<$F51+($G51*$I51)),"➤",""),"") | O51: =IF($I51>0%,IF(AND(O$16>=$F51,O$16<$F51+($G51*$I51)),"➤",""),"") | P51: =IF($I51>0%,IF(AND(P$16>=$F51,P$16<$F51+($G51*$I51)),"➤",""),"") | Q51: =IF($I51>0%,IF(AND(Q$16>=$F51,Q$16<$F51+($G51*$I51)),"➤",""),"") | R51: =IF($I51>0%,IF(AND(R$16>=$F51,R$16<$F51+($G51*$I51)),"➤",""),"") | S51: =IF($I51>0%,IF(AND(S$16>=$F51,S$16<$F51+($G51*$I51)),"➤",""),"") | ... SW51: =IF($I51>0%,IF(AND(SW$16>=$F51,SW$16<$F51+($G51*$I51)),"➤",""),"")
...

Sheet Configuracion
I2: * Se puede Excluir hasta 30 Dias
B3: Ingresar Datos | C3: N° | D3: Responsables | F3: Ingresar Datos | G3: Estados | I3: Fechas No consideradas | J3: Excluir Fechas
C4: 1 | D4: Yadhira Saavedra | G4: Sin Empezar | J4: 44150
C5: 2 | D5: Hector Montes | G5: En Proceso
C6: 3 | D6: Yimy Flores | G6: Completado
C7: 4 | D7: Edson Alabrin | G7: Atrasado
C8: 5
C9: 6
C10: 7
C11: 8
C12: 9
C13: 10
C14: 11
C15: 12
C16: 13
C17: 14
C18: 15
C19: 16
... C23: 20

Sheet Resultados
D3: Avance
B4: Actividades | C4: =COUNTA('Tallerdata.com'!D19:D30,'Tallerdata.com'!D32:D41,'Tallerdata.com'!D43:D52,'Tallerdata.com'!D54:D302) -> 12 | D4: =C4 -> 12
B5: =Configuracion!G4 -> Sin Empezar | C5: =COUNTIF('Tallerdata.com'!$J$19:$J$302,B5) -> 0
B6: =Configuracion!G5 -> En Proceso | C6: =COUNTIF('Tallerdata.com'!$J$19:$J$302,B6) -> 0 | D6: =IFERROR(AVERAGEIF('Tallerdata.com'!J19:J302,B6,'Tallerdata.com'!I19:I302),0)*C6 -> 0
B7: =Configuracion!G6 -> Completado | C7: =COUNTIF('Tallerdata.com'!$J$19:$J$302,B7) -> 12 | D7: =C7 -> 12
B8: =Configuracion!G7 -> Atrasado | C8: =COUNTIF('Tallerdata.com'!$J$19:$J$302,B8) -> 0 | D8: =IFERROR(AVERAGEIF('Tallerdata.com'!J19:J302,B8,'Tallerdata.com'!I19:I302),0)*C8 -> 0
B10: Total de Avance | D10: =+IFERROR((D6+D7+D8)/D4,0) -> 1
B14: * Tenga en consideracion esta Hoja Evitar de Realizar cambios

Sheet Fechas
A1: * Tenga en consideracion esta Hoja Evitar de Realizar cambios | F1: Total dias Excluidos
F2: =COUNTIF(F4:F509,1) -> 0
A3: Fechas Excluidas | C3: Excluir | D3: Resultado | F3: Exclusiones | G3: Texto Dia | H3: Fecha Cronograma | I3: Fechas Excluidas | J3: Excluir Sab-Dom | K3: Indice | L3: Cronograma | N3: Indice | O3: Cronograma Final
A4: =Configuracion!J4 -> 44150 | C4: Sábado | D4: =FALSE() -> FALSE | F4: =IF(OR(I4=1,J4=1),1,0) -> 0 | G4: =TEXT(H4,"DDD") -> vie | H4: ='Tallerdata.com'!P4 -> 46136 | I4: =IFERROR(IF(VLOOKUP(H4,$A$4:$A$33,1,0),1,0),0) -> 0 | J4: =IF(AND($D$4=TRUE(),G4="Sáb"),1,IF(AND($D$5=TRUE(),G4="Dom"),1,0)) -> 0 | K4: =IF(L4="No",0,1) -> 1 | L4: =IF(AND(I4=0,J4=0),H4,"NO") -> 46136 | N4: 1 | O4: =IFERROR(VLOOKUP(N4,$K$4:$L$509,2,0),"") -> 46136
A5: =Configuracion!J5 -> 0 | C5: Domingo | D5: =FALSE() -> FALSE | F5: =IF(OR(I5=1,J5=1),1,0) -> 0 | G5: =TEXT(H5,"DDD") -> sáb | H5: =IF(H4>='Tallerdata.com'!$X$4,NA(),H4+1) -> 46137 | I5: =IFERROR(IF(VLOOKUP(H5,$A$4:$A$33,1,0),1,0),0) -> 0 | J5: =IF(AND($D$4=TRUE(),G5="Sáb"),1,IF(AND($D$5=TRUE(),G5="Dom"),1,0)) -> 0 | K5: =IF(L5="No",K4,K4+1) -> 2 | L5: =IF(AND(I5=0,J5=0),H5,"NO") -> 46137 | N5: =N4+1 -> 2 | O5: =IFERROR(VLOOKUP(N5,$K$4:$L$509,2,0),"") -> 46137
A6: =Configuracion!J6 -> 0 | F6: =IF(OR(I6=1,J6=1),1,0) -> 0 | G6: =TEXT(H6,"DDD") -> dom | H6: =IF(H5>='Tallerdata.com'!$X$4,NA(),H5+1) -> 46138 | I6: =IFERROR(IF(VLOOKUP(H6,$A$4:$A$33,1,0),1,0),0) -> 0 | J6: =IF(AND($D$4=TRUE(),G6="Sáb"),1,IF(AND($D$5=TRUE(),G6="Dom"),1,0)) -> 0 | K6: =IF(L6="No",K5,K5+1) -> 3 | L6: =IF(AND(I6=0,J6=0),H6,"NO") -> 46138 | N6: =N5+1 -> 3 | O6: =IFERROR(VLOOKUP(N6,$K$4:$L$509,2,0),"") -> 46138
A7: =Configuracion!J7 -> 0 | F7: =IF(OR(I7=1,J7=1),1,0) -> 0 | G7: =TEXT(H7,"DDD") -> lun | H7: =IF(H6>='Tallerdata.com'!$X$4,NA(),H6+1) -> 46139 | I7: =IFERROR(IF(VLOOKUP(H7,$A$4:$A$33,1,0),1,0),0) -> 0 | J7: =IF(AND($D$4=TRUE(),G7="Sáb"),1,IF(AND($D$5=TRUE(),G7="Dom"),1,0)) -> 0 | K7: =IF(L7="No",K6,K6+1) -> 4 | L7: =IF(AND(I7=0,J7=0),H7,"NO") -> 46139 | N7: =N6+1 -> 4 | O7: =IFERROR(VLOOKUP(N7,$K$4:$L$509,2,0),"") -> 46139
A8: =Configuracion!J8 -> 0 | F8: =IF(OR(I8=1,J8=1),1,0) -> 0 | G8: =TEXT(H8,"DDD") -> mar | H8: =IF(H7>='Tallerdata.com'!$X$4,NA(),H7+1) -> 46140 | I8: =IFERROR(IF(VLOOKUP(H8,$A$4:$A$33,1,0),1,0),0) -> 0 | J8: =IF(AND($D$4=TRUE(),G8="Sáb"),1,IF(AND($D$5=TRUE(),G8="Dom"),1,0)) -> 0 | K8: =IF(L8="No",K7,K7+1) -> 5 | L8: =IF(AND(I8=0,J8=0),H8,"NO") -> 46140 | N8: =N7+1 -> 5 | O8: =IFERROR(VLOOKUP(N8,$K$4:$L$509,2,0),"") -> 46140
A9: =Configuracion!J9 -> 0 | C9: Fecha Ini | D9: ='Tallerdata.com'!P4 -> 46136 | F9: =IF(OR(I9=1,J9=1),1,0) -> 0 | G9: =TEXT(H9,"DDD") -> mié | H9: =IF(H8>='Tallerdata.com'!$X$4,NA(),H8+1) -> 46141 | I9: =IFERROR(IF(VLOOKUP(H9,$A$4:$A$33,1,0),1,0),0) -> 0 | J9: =IF(AND($D$4=TRUE(),G9="Sáb"),1,IF(AND($D$5=TRUE(),G9="Dom"),1,0)) -> 0 | K9: =IF(L9="No",K8,K8+1) -> 6 | L9: =IF(AND(I9=0,J9=0),H9,"NO") -> 46141 | N9: =N8+1 -> 6 | O9: =IFERROR(VLOOKUP(N9,$K$4:$L$509,2,0),"") -> 46141
A10: =Configuracion!J10 -> 0 | C10: Fecha Fin | D10: ='Tallerdata.com'!X4 -> 46218 | F10: =IF(OR(I10=1,J10=1),1,0) -> 0 | G10: =TEXT(H10,"DDD") -> jue | H10: =IF(H9>='Tallerdata.com'!$X$4,NA(),H9+1) -> 46142 | I10: =IFERROR(IF(VLOOKUP(H10,$A$4:$A$33,1,0),1,0),0) -> 0 | J10: =IF(AND($D$4=TRUE(),G10="Sáb"),1,IF(AND($D$5=TRUE(),G10="Dom"),1,0)) -> 0 | K10: =IF(L10="No",K9,K9+1) -> 7 | L10: =IF(AND(I10=0,J10=0),H10,"NO") -> 46142 | N10: =N9+1 -> 7 | O10: =IFERROR(VLOOKUP(N10,$K$4:$L$509,2,0),"") -> 46142
A11: =Configuracion!J11 -> 0 | F11: =IF(OR(I11=1,J11=1),1,0) -> 0 | G11: =TEXT(H11,"DDD") -> vie | H11: =IF(H10>='Tallerdata.com'!$X$4,NA(),H10+1) -> 46143 | I11: =IFERROR(IF(VLOOKUP(H11,$A$4:$A$33,1,0),1,0),0) -> 0 | J11: =IF(AND($D$4=TRUE(),G11="Sáb"),1,IF(AND($D$5=TRUE(),G11="Dom"),1,0)) -> 0 | K11: =IF(L11="No",K10,K10+1) -> 8 | L11: =IF(AND(I11=0,J11=0),H11,"NO") -> 46143 | N11: =N10+1 -> 8 | O11: =IFERROR(VLOOKUP(N11,$K$4:$L$509,2,0),"") -> 46143
A12: =Configuracion!J12 -> 0 | C12: Sin Exclusion | F12: =IF(OR(I12=1,J12=1),1,0) -> 0 | G12: =TEXT(H12,"DDD") -> sáb | H12: =IF(H11>='Tallerdata.com'!$X$4,NA(),H11+1) -> 46144 | I12: =IFERROR(IF(VLOOKUP(H12,$A$4:$A$33,1,0),1,0),0) -> 0 | J12: =IF(AND($D$4=TRUE(),G12="Sáb"),1,IF(AND($D$5=TRUE(),G12="Dom"),1,0)) -> 0 | K12: =IF(L12="No",K11,K11+1) -> 9 | L12: =IF(AND(I12=0,J12=0),H12,"NO") -> 46144 | N12: =N11+1 -> 9 | O12: =IFERROR(VLOOKUP(N12,$K$4:$L$509,2,0),"") -> 46144
A13: =Configuracion!J13 -> 0 | C13: Meses | D13: =DATEDIF(D9,D10,"m") -> 2 | F13: =IF(OR(I13=1,J13=1),1,0) -> 0 | G13: =TEXT(H13,"DDD") -> dom | H13: =IF(H12>='Tallerdata.com'!$X$4,NA(),H12+1) -> 46145 | I13: =IFERROR(IF(VLOOKUP(H13,$A$4:$A$33,1,0),1,0),0) -> 0 | J13: =IF(AND($D$4=TRUE(),G13="Sáb"),1,IF(AND($D$5=TRUE(),G13="Dom"),1,0)) -> 0 | K13: =IF(L13="No",K12,K12+1) -> 10 | L13: =IF(AND(I13=0,J13=0),H13,"NO") -> 46145 | N13: =N12+1 -> 10 | O13: =IFERROR(VLOOKUP(N13,$K$4:$L$509,2,0),"") -> 46145
A14: =Configuracion!J14 -> 0 | C14: Dias | D14: =DATEDIF(D9,D10,"md")+1 -> 22 | F14: =IF(OR(I14=1,J14=1),1,0) -> 0 | G14: =TEXT(H14,"DDD") -> lun | H14: =IF(H13>='Tallerdata.com'!$X$4,NA(),H13+1) -> 46146 | I14: =IFERROR(IF(VLOOKUP(H14,$A$4:$A$33,1,0),1,0),0) -> 0 | J14: =IF(AND($D$4=TRUE(),G14="Sáb"),1,IF(AND($D$5=TRUE(),G14="Dom"),1,0)) -> 0 | K14: =IF(L14="No",K13,K13+1) -> 11 | L14: =IF(AND(I14=0,J14=0),H14,"NO") -> 46146 | N14: =N13+1 -> 11 | O14: =IFERROR(VLOOKUP(N14,$K$4:$L$509,2,0),"") -> 46146
A15: =Configuracion!J15 -> 0 | F15: =IF(OR(I15=1,J15=1),1,0) -> 0 | G15: =TEXT(H15,"DDD") -> mar | H15: =IF(H14>='Tallerdata.com'!$X$4,NA(),H14+1) -> 46147 | I15: =IFERROR(IF(VLOOKUP(H15,$A$4:$A$33,1,0),1,0),0) -> 0 | J15: =IF(AND($D$4=TRUE(),G15="Sáb"),1,IF(AND($D$5=TRUE(),G15="Dom"),1,0)) -> 0 | K15: =IF(L15="No",K14,K14+1) -> 12 | L15: =IF(AND(I15=0,J15=0),H15,"NO") -> 46147 | N15: =N14+1 -> 12 | O15: =IFERROR(VLOOKUP(N15,$K$4:$L$509,2,0),"") -> 46147
A16: =Configuracion!J16 -> 0 | C16: Dias Excluidos | D16: =F2 -> 0 | F16: =IF(OR(I16=1,J16=1),1,0) -> 0 | G16: =TEXT(H16,"DDD") -> mié | H16: =IF(H15>='Tallerdata.com'!$X$4,NA(),H15+1) -> 46148 | I16: =IFERROR(IF(VLOOKUP(H16,$A$4:$A$33,1,0),1,0),0) -> 0 | J16: =IF(AND($D$4=TRUE(),G16="Sáb"),1,IF(AND($D$5=TRUE(),G16="Dom"),1,0)) -> 0 | K16: =IF(L16="No",K15,K15+1) -> 13 | L16: =IF(AND(I16=0,J16=0),H16,"NO") -> 46148 | N16: =N15+1 -> 13 | O16: =IFERROR(VLOOKUP(N16,$K$4:$L$509,2,0),"") -> 46148
A17: =Configuracion!J17 -> 0 | F17: =IF(OR(I17=1,J17=1),1,0) -> 0 | G17: =TEXT(H17,"DDD") -> jue | H17: =IF(H16>='Tallerdata.com'!$X$4,NA(),H16+1) -> 46149 | I17: =IFERROR(IF(VLOOKUP(H17,$A$4:$A$33,1,0),1,0),0) -> 0 | J17: =IF(AND($D$4=TRUE(),G17="Sáb"),1,IF(AND($D$5=TRUE(),G17="Dom"),1,0)) -> 0 | K17: =IF(L17="No",K16,K16+1) -> 14 | L17: =IF(AND(I17=0,J17=0),H17,"NO") -> 46149 | N17: =N16+1 -> 14 | O17: =IFERROR(VLOOKUP(N17,$K$4:$L$509,2,0),"") -> 46149
A18: =Configuracion!J18 -> 0 | C18: Fecha Fin Nueva | D18: =D10-D16 -> 46218 | F18: =IF(OR(I18=1,J18=1),1,0) -> 0 | G18: =TEXT(H18,"DDD") -> vie | H18: =IF(H17>='Tallerdata.com'!$X$4,NA(),H17+1) -> 46150 | I18: =IFERROR(IF(VLOOKUP(H18,$A$4:$A$33,1,0),1,0),0) -> 0 | J18: =IF(AND($D$4=TRUE(),G18="Sáb"),1,IF(AND($D$5=TRUE(),G18="Dom"),1,0)) -> 0 | K18: =IF(L18="No",K17,K17+1) -> 15 | L18: =IF(AND(I18=0,J18=0),H18,"NO") -> 46150 | N18: =N17+1 -> 15 | O18: =IFERROR(VLOOKUP(N18,$K$4:$L$509,2,0),"") -> 46150
A19: =Configuracion!J19 -> 0 | F19: =IF(OR(I19=1,J19=1),1,0) -> 0 | G19: =TEXT(H19,"DDD") -> sáb | H19: =IF(H18>='Tallerdata.com'!$X$4,NA(),H18+1) -> 46151 | I19: =IFERROR(IF(VLOOKUP(H19,$A$4:$A$33,1,0),1,0),0) -> 0 | J19: =IF(AND($D$4=TRUE(),G19="Sáb"),1,IF(AND($D$5=TRUE(),G19="Dom"),1,0)) -> 0 | K19: =IF(L19="No",K18,K18+1) -> 16 | L19: =IF(AND(I19=0,J19=0),H19,"NO") -> 46151 | N19: =N18+1 -> 16 | O19: =IFERROR(VLOOKUP(N19,$K$4:$L$509,2,0),"") -> 46151
A20: =Configuracion!J20 -> 0 | C20: Con Exclusion | F20: =IF(OR(I20=1,J20=1),1,0) -> 0 | G20: =TEXT(H20,"DDD") -> dom | H20: =IF(H19>='Tallerdata.com'!$X$4,NA(),H19+1) -> 46152 | I20: =IFERROR(IF(VLOOKUP(H20,$A$4:$A$33,1,0),1,0),0) -> 0 | J20: =IF(AND($D$4=TRUE(),G20="Sáb"),1,IF(AND($D$5=TRUE(),G20="Dom"),1,0)) -> 0 | K20: =IF(L20="No",K19,K19+1) -> 17 | L20: =IF(AND(I20=0,J20=0),H20,"NO") -> 46152 | N20: =N19+1 -> 17 | O20: =IFERROR(VLOOKUP(N20,$K$4:$L$509,2,0),"") -> 46152
A21: =Configuracion!J21 -> 0 | C21: Meses | D21: =DATEDIF(D9,D18,"m") -> 2 | F21: =IF(OR(I21=1,J21=1),1,0) -> 0 | G21: =TEXT(H21,"DDD") -> lun | H21: =IF(H20>='Tallerdata.com'!$X$4,NA(),H20+1) -> 46153 | I21: =IFERROR(IF(VLOOKUP(H21,$A$4:$A$33,1,0),1,0),0) -> 0 | J21: =IF(AND($D$4=TRUE(),G21="Sáb"),1,IF(AND($D$5=TRUE(),G21="Dom"),1,0)) -> 0 | K21: =IF(L21="No",K20,K20+1) -> 18 | L21: =IF(AND(I21=0,J21=0),H21,"NO") -> 46153 | N21: =N20+1 -> 18 | O21: =IFERROR(VLOOKUP(N21,$K$4:$L$509,2,0),"") -> 46153
A22: =Configuracion!J22 -> 0 | C22: Dias | D22: =DATEDIF(D9,D18,"md")+1 -> 22 | F22: =IF(OR(I22=1,J22=1),1,0) -> 0 | G22: =TEXT(H22,"DDD") -> mar | H22: =IF(H21>='Tallerdata.com'!$X$4,NA(),H21+1) -> 46154 | I22: =IFERROR(IF(VLOOKUP(H22,$A$4:$A$33,1,0),1,0),0) -> 0 | J22: =IF(AND($D$4=TRUE(),G22="Sáb"),1,IF(AND($D$5=TRUE(),G22="Dom"),1,0)) -> 0 | K22: =IF(L22="No",K21,K21+1) -> 19 | L22: =IF(AND(I22=0,J22=0),H22,"NO") -> 46154 | N22: =N21+1 -> 19 | O22: =IFERROR(VLOOKUP(N22,$K$4:$L$509,2,0),"") -> 46154
A23: =Configuracion!J23 -> 0 | F23: =IF(OR(I23=1,J23=1),1,0) -> 0 | G23: =TEXT(H23,"DDD") -> mié | H23: =IF(H22>='Tallerdata.com'!$X$4,NA(),H22+1) -> 46155 | I23: =IFERROR(IF(VLOOKUP(H23,$A$4:$A$33,1,0),1,0),0) -> 0 | J23: =IF(AND($D$4=TRUE(),G23="Sáb"),1,IF(AND($D$5=TRUE(),G23="Dom"),1,0)) -> 0 | K23: =IF(L23="No",K22,K22+1) -> 20 | L23: =IF(AND(I23=0,J23=0),H23,"NO") -> 46155 | N23: =N22+1 -> 20 | O23: =IFERROR(VLOOKUP(N23,$K$4:$L$509,2,0),"") -> 46155
A24: =Configuracion!J24 -> 0 | F24: =IF(OR(I24=1,J24=1),1,0) -> 0 | G24: =TEXT(H24,"DDD") -> jue | H24: =IF(H23>='Tallerdata.com'!$X$4,NA(),H23+1) -> 46156 | I24: =IFERROR(IF(VLOOKUP(H24,$A$4:$A$33,1,0),1,0),0) -> 0 | J24: =IF(AND($D$4=TRUE(),G24="Sáb"),1,IF(AND($D$5=TRUE(),G24="Dom"),1,0)) -> 0 | K24: =IF(L24="No",K23,K23+1) -> 21 | L24: =IF(AND(I24=0,J24=0),H24,"NO") -> 46156 | N24: =N23+1 -> 21 | O24: =IFERROR(VLOOKUP(N24,$K$4:$L$509,2,0),"") -> 46156
A25: =Configuracion!J25 -> 0 | F25: =IF(OR(I25=1,J25=1),1,0) -> 0 | G25: =TEXT(H25,"DDD") -> vie | H25: =IF(H24>='Tallerdata.com'!$X$4,NA(),H24+1) -> 46157 | I25: =IFERROR(IF(VLOOKUP(H25,$A$4:$A$33,1,0),1,0),0) -> 0 | J25: =IF(AND($D$4=TRUE(),G25="Sáb"),1,IF(AND($D$5=TRUE(),G25="Dom"),1,0)) -> 0 | K25: =IF(L25="No",K24,K24+1) -> 22 | L25: =IF(AND(I25=0,J25=0),H25,"NO") -> 46157 | N25: =N24+1 -> 22 | O25: =IFERROR(VLOOKUP(N25,$K$4:$L$509,2,0),"") -> 46157
A26: =Configuracion!J26 -> 0 | F26: =IF(OR(I26=1,J26=1),1,0) -> 0 | G26: =TEXT(H26,"DDD") -> sáb | H26: =IF(H25>='Tallerdata.com'!$X$4,NA(),H25+1) -> 46158 | I26: =IFERROR(IF(VLOOKUP(H26,$A$4:$A$33,1,0),1,0),0) -> 0 | J26: =IF(AND($D$4=TRUE(),G26="Sáb"),1,IF(AND($D$5=TRUE(),G26="Dom"),1,0)) -> 0 | K26: =IF(L26="No",K25,K25+1) -> 23 | L26: =IF(AND(I26=0,J26=0),H26,"NO") -> 46158 | N26: =N25+1 -> 23 | O26: =IFERROR(VLOOKUP(N26,$K$4:$L$509,2,0),"") -> 46158
A27: =Configuracion!J27 -> 0 | F27: =IF(OR(I27=1,J27=1),1,0) -> 0 | G27: =TEXT(H27,"DDD") -> dom | H27: =IF(H26>='Tallerdata.com'!$X$4,NA(),H26+1) -> 46159 | I27: =IFERROR(IF(VLOOKUP(H27,$A$4:$A$33,1,0),1,0),0) -> 0 | J27: =IF(AND($D$4=TRUE(),G27="Sáb"),1,IF(AND($D$5=TRUE(),G27="Dom"),1,0)) -> 0 | K27: =IF(L27="No",K26,K26+1) -> 24 | L27: =IF(AND(I27=0,J27=0),H27,"NO") -> 46159 | N27: =N26+1 -> 24 | O27: =IFERROR(VLOOKUP(N27,$K$4:$L$509,2,0),"") -> 46159
A28: =Configuracion!J28 -> 0 | F28: =IF(OR(I28=1,J28=1),1,0) -> 0 | G28: =TEXT(H28,"DDD") -> lun | H28: =IF(H27>='Tallerdata.com'!$X$4,NA(),H27+1) -> 46160 | I28: =IFERROR(IF(VLOOKUP(H28,$A$4:$A$33,1,0),1,0),0) -> 0 | J28: =IF(AND($D$4=TRUE(),G28="Sáb"),1,IF(AND($D$5=TRUE(),G28="Dom"),1,0)) -> 0 | K28: =IF(L28="No",K27,K27+1) -> 25 | L28: =IF(AND(I28=0,J28=0),H28,"NO") -> 46160 | N28: =N27+1 -> 25 | O28: =IFERROR(VLOOKUP(N28,$K$4:$L$509,2,0),"") -> 46160
A29: =Configuracion!J29 -> 0 | F29: =IF(OR(I29=1,J29=1),1,0) -> 0 | G29: =TEXT(H29,"DDD") -> mar | H29: =IF(H28>='Tallerdata.com'!$X$4,NA(),H28+1) -> 46161 | I29: =IFERROR(IF(VLOOKUP(H29,$A$4:$A$33,1,0),1,0),0) -> 0 | J29: =IF(AND($D$4=TRUE(),G29="Sáb"),1,IF(AND($D$5=TRUE(),G29="Dom"),1,0)) -> 0 | K29: =IF(L29="No",K28,K28+1) -> 26 | L29: =IF(AND(I29=0,J29=0),H29,"NO") -> 46161 | N29: =N28+1 -> 26 | O29: =IFERROR(VLOOKUP(N29,$K$4:$L$509,2,0),"") -> 46161
A30: =Configuracion!J30 -> 0 | F30: =IF(OR(I30=1,J30=1),1,0) -> 0 | G30: =TEXT(H30,"DDD") -> mié | H30: =IF(H29>='Tallerdata.com'!$X$4,NA(),H29+1) -> 46162 | I30: =IFERROR(IF(VLOOKUP(H30,$A$4:$A$33,1,0),1,0),0) -> 0 | J30: =IF(AND($D$4=TRUE(),G30="Sáb"),1,IF(AND($D$5=TRUE(),G30="Dom"),1,0)) -> 0 | K30: =IF(L30="No",K29,K29+1) -> 27 | L30: =IF(AND(I30=0,J30=0),H30,"NO") -> 46162 | N30: =N29+1 -> 27 | O30: =IFERROR(VLOOKUP(N30,$K$4:$L$509,2,0),"") -> 46162
A31: =Configuracion!J31 -> 0 | F31: =IF(OR(I31=1,J31=1),1,0) -> 0 | G31: =TEXT(H31,"DDD") -> jue | H31: =IF(H30>='Tallerdata.com'!$X$4,NA(),H30+1) -> 46163 | I31: =IFERROR(IF(VLOOKUP(H31,$A$4:$A$33,1,0),1,0),0) -> 0 | J31: =IF(AND($D$4=TRUE(),G31="Sáb"),1,IF(AND($D$5=TRUE(),G31="Dom"),1,0)) -> 0 | K31: =IF(L31="No",K30,K30+1) -> 28 | L31: =IF(AND(I31=0,J31=0),H31,"NO") -> 46163 | N31: =N30+1 -> 28 | O31: =IFERROR(VLOOKUP(N31,$K$4:$L$509,2,0),"") -> 46163
A32: =Configuracion!J32 -> 0 | F32: =IF(OR(I32=1,J32=1),1,0) -> 0 | G32: =TEXT(H32,"DDD") -> vie | H32: =IF(H31>='Tallerdata.com'!$X$4,NA(),H31+1) -> 46164 | I32: =IFERROR(IF(VLOOKUP(H32,$A$4:$A$33,1,0),1,0),0) -> 0 | J32: =IF(AND($D$4=TRUE(),G32="Sáb"),1,IF(AND($D$5=TRUE(),G32="Dom"),1,0)) -> 0 | K32: =IF(L32="No",K31,K31+1) -> 29 | L32: =IF(AND(I32=0,J32=0),H32,"NO") -> 46164 | N32: =N31+1 -> 29 | O32: =IFERROR(VLOOKUP(N32,$K$4:$L$509,2,0),"") -> 46164
A33: =Configuracion!J33 -> 0 | F33: =IF(OR(I33=1,J33=1),1,0) -> 0 | G33: =TEXT(H33,"DDD") -> sáb | H33: =IF(H32>='Tallerdata.com'!$X$4,NA(),H32+1) -> 46165 | I33: =IFERROR(IF(VLOOKUP(H33,$A$4:$A$33,1,0),1,0),0) -> 0 | J33: =IF(AND($D$4=TRUE(),G33="Sáb"),1,IF(AND($D$5=TRUE(),G33="Dom"),1,0)) -> 0 | K33: =IF(L33="No",K32,K32+1) -> 30 | L33: =IF(AND(I33=0,J33=0),H33,"NO") -> 46165 | N33: =N32+1 -> 30 | O33: =IFERROR(VLOOKUP(N33,$K$4:$L$509,2,0),"") -> 46165
F34: =IF(OR(I34=1,J34=1),1,0) -> 0 | G34: =TEXT(H34,"DDD") -> dom | H34: =IF(H33>='Tallerdata.com'!$X$4,NA(),H33+1) -> 46166 | I34: =IFERROR(IF(VLOOKUP(H34,$A$4:$A$33,1,0),1,0),0) -> 0 | J34: =IF(AND($D$4=TRUE(),G34="Sáb"),1,IF(AND($D$5=TRUE(),G34="Dom"),1,0)) -> 0 | K34: =IF(L34="No",K33,K33+1) -> 31 | L34: =IF(AND(I34=0,J34=0),H34,"NO") -> 46166 | N34: =N33+1 -> 31 | O34: =IFERROR(VLOOKUP(N34,$K$4:$L$509,2,0),"") -> 46166
F35: =IF(OR(I35=1,J35=1),1,0) -> 0 | G35: =TEXT(H35,"DDD") -> lun | H35: =IF(H34>='Tallerdata.com'!$X$4,NA(),H34+1) -> 46167 | I35: =IFERROR(IF(VLOOKUP(H35,$A$4:$A$33,1,0),1,0),0) -> 0 | J35: =IF(AND($D$4=TRUE(),G35="Sáb"),1,IF(AND($D$5=TRUE(),G35="Dom"),1,0)) -> 0 | K35: =IF(L35="No",K34,K34+1) -> 32 | L35: =IF(AND(I35=0,J35=0),H35,"NO") -> 46167 | N35: =N34+1 -> 32 | O35: =IFERROR(VLOOKUP(N35,$K$4:$L$509,2,0),"") -> 46167
F36: =IF(OR(I36=1,J36=1),1,0) -> 0 | G36: =TEXT(H36,"DDD") -> mar | H36: =IF(H35>='Tallerdata.com'!$X$4,NA(),H35+1) -> 46168 | I36: =IFERROR(IF(VLOOKUP(H36,$A$4:$A$33,1,0),1,0),0) -> 0 | J36: =IF(AND($D$4=TRUE(),G36="Sáb"),1,IF(AND($D$5=TRUE(),G36="Dom"),1,0)) -> 0 | K36: =IF(L36="No",K35,K35+1) -> 33 | L36: =IF(AND(I36=0,J36=0),H36,"NO") -> 46168 | N36: =N35+1 -> 33 | O36: =IFERROR(VLOOKUP(N36,$K$4:$L$509,2,0),"") -> 46168
F37: =IF(OR(I37=1,J37=1),1,0) -> 0 | G37: =TEXT(H37,"DDD") -> mié | H37: =IF(H36>='Tallerdata.com'!$X$4,NA(),H36+1) -> 46169 | I37: =IFERROR(IF(VLOOKUP(H37,$A$4:$A$33,1,0),1,0),0) -> 0 | J37: =IF(AND($D$4=TRUE(),G37="Sáb"),1,IF(AND($D$5=TRUE(),G37="Dom"),1,0)) -> 0 | K37: =IF(L37="No",K36,K36+1) -> 34 | L37: =IF(AND(I37=0,J37=0),H37,"NO") -> 46169 | N37: =N36+1 -> 34 | O37: =IFERROR(VLOOKUP(N37,$K$4:$L$509,2,0),"") -> 46169
F38: =IF(OR(I38=1,J38=1),1,0) -> 0 | G38: =TEXT(H38,"DDD") -> jue | H38: =IF(H37>='Tallerdata.com'!$X$4,NA(),H37+1) -> 46170 | I38: =IFERROR(IF(VLOOKUP(H38,$A$4:$A$33,1,0),1,0),0) -> 0 | J38: =IF(AND($D$4=TRUE(),G38="Sáb"),1,IF(AND($D$5=TRUE(),G38="Dom"),1,0)) -> 0 | K38: =IF(L38="No",K37,K37+1) -> 35 | L38: =IF(AND(I38=0,J38=0),H38,"NO") -> 46170 | N38: =N37+1 -> 35 | O38: =IFERROR(VLOOKUP(N38,$K$4:$L$509,2,0),"") -> 46170
F39: =IF(OR(I39=1,J39=1),1,0) -> 0 | G39: =TEXT(H39,"DDD") -> vie | H39: =IF(H38>='Tallerdata.com'!$X$4,NA(),H38+1) -> 46171 | I39: =IFERROR(IF(VLOOKUP(H39,$A$4:$A$33,1,0),1,0),0) -> 0 | J39: =IF(AND($D$4=TRUE(),G39="Sáb"),1,IF(AND($D$5=TRUE(),G39="Dom"),1,0)) -> 0 | K39: =IF(L39="No",K38,K38+1) -> 36 | L39: =IF(AND(I39=0,J39=0),H39,"NO") -> 46171 | N39: =N38+1 -> 36 | O39: =IFERROR(VLOOKUP(N39,$K$4:$L$509,2,0),"") -> 46171
F40: =IF(OR(I40=1,J40=1),1,0) -> 0 | G40: =TEXT(H40,"DDD") -> sáb | H40: =IF(H39>='Tallerdata.com'!$X$4,NA(),H39+1) -> 46172 | I40: =IFERROR(IF(VLOOKUP(H40,$A$4:$A$33,1,0),1,0),0) -> 0 | J40: =IF(AND($D$4=TRUE(),G40="Sáb"),1,IF(AND($D$5=TRUE(),G40="Dom"),1,0)) -> 0 | K40: =IF(L40="No",K39,K39+1) -> 37 | L40: =IF(AND(I40=0,J40=0),H40,"NO") -> 46172 | N40: =N39+1 -> 37 | O40: =IFERROR(VLOOKUP(N40,$K$4:$L$509,2,0),"") -> 46172
...
